Database access not allowed, use the "django_db" mark, or the "db" or "transactional_db" fixtures to enable it.
Traceback (most recent call last):
  File "/home/user/sources/scraping/models/netkeiba_pages.py", line 142, in update_html
    self.__update_html(driver)
  File "/home/user/sources/scraping/models/login_for_scraping.py", line 51, in wrapper
    LoginForScraping.objects.get_or_create(domain=domain)
  File "/usr/local/lib/python3.10/site-packages/django/db/models/manager.py", line 87, in manager_method
    return getattr(self.get_queryset(), name)(*args, **kwargs)
  File "/usr/local/lib/python3.10/site-packages/django/db/models/query.py", line 948, in get_or_create
    return self.get(**kwargs), False
  File "/usr/local/lib/python3.10/site-packages/django/db/models/query.py", line 645, in get
    num = len(clone)
  File "/usr/local/lib/python3.10/site-packages/django/db/models/query.py", line 382, in __len__
    self._fetch_all()
  File "/usr/local/lib/python3.10/site-packages/django/db/models/query.py", line 1928, in _fetch_all
    self._result_cache = list(self._iterable_class(self))
  File "/usr/local/lib/python3.10/site-packages/django/db/models/query.py", line 91, in __iter__
    results = compiler.execute_sql(
  File "/usr/local/lib/python3.10/site-packages/django/db/models/sql/compiler.py", line 1560, in execute_sql
    cursor = self.connection.cursor()
  File "/usr/local/lib/python3.10/site-packages/django/utils/asyncio.py", line 26, in inner
    return func(*args, **kwargs)
  File "/usr/local/lib/python3.10/site-packages/django/db/backends/base/base.py", line 316, in cursor
    return self._cursor()
  File "/usr/local/lib/python3.10/site-packages/django/db/backends/base/base.py", line 292, in _cursor
    self.ensure_connection()
  File "/usr/local/lib/python3.10/site-packages/pytest_django/plugin.py", line 803, in _blocking_wrapper
    raise RuntimeError(
RuntimeError: Database access not allowed, use the "django_db" mark, or the "db" or "transactional_db" fixtures to enable it.
2024-06-22 08:51:51.031335+00:00: Empty module name
Traceback (most recent call last):
  File "/home/user/sources/event_schedules/models.py", line 119, in doevent
    event.first().doevent()
  File "/home/user/sources/event_schedules/models.py", line 100, in doevent
    raise e
  File "/home/user/sources/event_schedules/models.py", line 90, in doevent
    module = __import__(self.event_function.split(".")[0])
ValueError: Empty module name


2024-06-22 08:55:49.720565+00:00: 'Manager' object has no attribute 'create(status=4)'
Traceback (most recent call last):
  File "/home/user/sources/event_schedules/models.py", line 119, in doevent
    return event.first().doevent()
  File "/home/user/sources/event_schedules/models.py", line 100, in doevent
    raise e
  File "/home/user/sources/event_schedules/models.py", line 92, in doevent
    module = getattr(module, i)
AttributeError: 'Manager' object has no attribute 'create(status=4)'


2024-06-22 08:58:51.681772+00:00: __import__() missing required argument 'name' (pos 1)
Traceback (most recent call last):
  File "/home/user/sources/event_schedules/models.py", line 119, in doevent
    return event.first().doevent()
  File "/home/user/sources/event_schedules/models.py", line 100, in doevent
    raise e
  File "/home/user/sources/event_schedules/models.py", line 90, in doevent
    module = __import__()
TypeError: __import__() missing required argument 'name' (pos 1)


2024-06-22 09:01:19.055707+00:00: Manager isn't accessible via Schedule instances
Traceback (most recent call last):
  File "/home/user/sources/event_schedules/models.py", line 91, in doevent
    exec(f"{self.event_function}()")
  File "<string>", line 1, in <module>
TypeError: 'Schedule' object is not callable

During handling of the above exception, another exception occurred:

Traceback (most recent call last):
  File "/home/user/sources/event_schedules/models.py", line 118, in doevent
    return event.first().doevent()
  File "/home/user/sources/event_schedules/models.py", line 96, in doevent
    event_history.save()
  File "/home/user/sources/event_schedules/models.py", line 15, in save
    variables = {property_: getattr(self.schedule, property_) for property_ in dir(self.schedule)}
  File "/home/user/sources/event_schedules/models.py", line 15, in <dictcomp>
    variables = {property_: getattr(self.schedule, property_) for property_ in dir(self.schedule)}
  File "/usr/local/lib/python3.10/site-packages/django/db/models/manager.py", line 186, in __get__
    raise AttributeError(
AttributeError: Manager isn't accessible via Schedule instances


2024-06-22 09:02:12.350137+00:00: Manager isn't accessible via Schedule instances
Traceback (most recent call last):
  File "/home/user/sources/event_schedules/models.py", line 91, in doevent
    exec(f"{self.event_function}()")
  File "<string>", line 1, in <module>
TypeError: 'Schedule' object is not callable

During handling of the above exception, another exception occurred:

Traceback (most recent call last):
  File "/home/user/sources/event_schedules/models.py", line 118, in doevent
    return event.first().doevent()
  File "/home/user/sources/event_schedules/models.py", line 96, in doevent
    event_history.save()
  File "/home/user/sources/event_schedules/models.py", line 15, in save
    variables = {property_: getattr(self.schedule, property_) for property_ in dir(self.schedule)}
  File "/home/user/sources/event_schedules/models.py", line 15, in <dictcomp>
    variables = {property_: getattr(self.schedule, property_) for property_ in dir(self.schedule)}
  File "/usr/local/lib/python3.10/site-packages/django/db/models/manager.py", line 186, in __get__
    raise AttributeError(
AttributeError: Manager isn't accessible via Schedule instances


2024-06-22 09:02:42.116208+00:00: Manager isn't accessible via Schedule instances
Traceback (most recent call last):
  File "/home/user/sources/event_schedules/models.py", line 91, in doevent
    exec(f"{self.event_function}()")
  File "<string>", line 1, in <module>
TypeError: 'Schedule' object is not callable

During handling of the above exception, another exception occurred:

Traceback (most recent call last):
  File "/home/user/sources/event_schedules/models.py", line 117, in doevent
    return event.first().doevent()
  File "/home/user/sources/event_schedules/models.py", line 95, in doevent
    event_history.save()
  File "/home/user/sources/event_schedules/models.py", line 15, in save
    variables = {property_: getattr(self.schedule, property_) for property_ in dir(self.schedule)}
  File "/home/user/sources/event_schedules/models.py", line 15, in <dictcomp>
    variables = {property_: getattr(self.schedule, property_) for property_ in dir(self.schedule)}
  File "/usr/local/lib/python3.10/site-packages/django/db/models/manager.py", line 186, in __get__
    raise AttributeError(
AttributeError: Manager isn't accessible via Schedule instances


2024-06-22 09:03:12.673515+00:00: Manager isn't accessible via Schedule instances
Traceback (most recent call last):
  File "/home/user/sources/event_schedules/models.py", line 91, in doevent
    exec(f"{self.event_function}()")
  File "<string>", line 1, in <module>
TypeError: 'Schedule' object is not callable

During handling of the above exception, another exception occurred:

Traceback (most recent call last):
  File "/home/user/sources/event_schedules/models.py", line 117, in doevent
    return event.first().doevent()
  File "/home/user/sources/event_schedules/models.py", line 95, in doevent
    event_history.save()
  File "/home/user/sources/event_schedules/models.py", line 15, in save
    variables = {property_: getattr(self.schedule, property_) for property_ in dir(self.schedule)}
  File "/home/user/sources/event_schedules/models.py", line 15, in <dictcomp>
    variables = {property_: getattr(self.schedule, property_) for property_ in dir(self.schedule)}
  File "/usr/local/lib/python3.10/site-packages/django/db/models/manager.py", line 186, in __get__
    raise AttributeError(
AttributeError: Manager isn't accessible via Schedule instances


2024-06-22 09:04:36.975678+00:00: 'Schedule' object is not callable
Traceback (most recent call last):
  File "/home/user/sources/event_schedules/models.py", line 122, in doevent
    return event.first().doevent()
  File "/home/user/sources/event_schedules/models.py", line 103, in doevent
    raise e
  File "/home/user/sources/event_schedules/models.py", line 96, in doevent
    exec(f"{self.event_function}()")
  File "<string>", line 1, in <module>
TypeError: 'Schedule' object is not callable


2024-06-22 09:05:53.102038+00:00: 'Schedule' object has no attribute 'schedule'
Traceback (most recent call last):
  File "/home/user/sources/event_schedules/models.py", line 122, in doevent
    return event.first().doevent()
  File "/home/user/sources/event_schedules/models.py", line 114, in doevent
    return str({property_: getattr(self.schedule, property_) for property_ in dir(self.schedule)})
AttributeError: 'Schedule' object has no attribute 'schedule'


2024-06-22 09:08:09.967491+00:00: 'Schedule' object has no attribute 'schedule'
Traceback (most recent call last):
  File "/home/user/sources/event_schedules/models.py", line 122, in doevent
    return event.first().doevent()
  File "/home/user/sources/event_schedules/models.py", line 114, in doevent
    return str({property_: getattr(self.schedule, property_) for property_ in dir(self.schedule)})
AttributeError: 'Schedule' object has no attribute 'schedule'


2024-06-22 09:25:24.848431+00:00: (1054, "Unknown column 'event_function' in 'field list'")
Traceback (most recent call last):
  File "/home/user/sources/event_schedules/models.py", line 97, in doevent
    exec("import {}".format(self.event_function.split(".")[0]))
  File "<string>", line 1
    import 
           ^
SyntaxError: invalid syntax

During handling of the above exception, another exception occurred:

Traceback (most recent call last):
  File "/usr/local/lib/python3.10/site-packages/django/db/backends/utils.py", line 105, in _execute
    return self.cursor.execute(sql, params)
  File "/usr/local/lib/python3.10/site-packages/django/db/backends/mysql/base.py", line 76, in execute
    return self.cursor.execute(query, args)
  File "/usr/local/lib/python3.10/site-packages/MySQLdb/cursors.py", line 179, in execute
    res = self._query(mogrified_query)
  File "/usr/local/lib/python3.10/site-packages/MySQLdb/cursors.py", line 330, in _query
    db.query(q)
  File "/usr/local/lib/python3.10/site-packages/MySQLdb/connections.py", line 261, in query
    _mysql.connection.query(self, query)
MySQLdb.OperationalError: (1054, "Unknown column 'event_function' in 'field list'")

The above exception was the direct cause of the following exception:

Traceback (most recent call last):
  File "/home/user/sources/event_schedules/models.py", line 124, in doevent
    return event.first().doevent()
  File "/home/user/sources/event_schedules/models.py", line 102, in doevent
    event_history.save()
  File "/home/user/sources/event_schedules/models.py", line 24, in save
    super().save()
  File "/usr/local/lib/python3.10/site-packages/django/db/models/base.py", line 822, in save
    self.save_base(
  File "/usr/local/lib/python3.10/site-packages/django/db/models/base.py", line 909, in save_base
    updated = self._save_table(
  File "/usr/local/lib/python3.10/site-packages/django/db/models/base.py", line 1071, in _save_table
    results = self._do_insert(
  File "/usr/local/lib/python3.10/site-packages/django/db/models/base.py", line 1112, in _do_insert
    return manager._insert(
  File "/usr/local/lib/python3.10/site-packages/django/db/models/manager.py", line 87, in manager_method
    return getattr(self.get_queryset(), name)(*args, **kwargs)
  File "/usr/local/lib/python3.10/site-packages/django/db/models/query.py", line 1847, in _insert
    return query.get_compiler(using=using).execute_sql(returning_fields)
  File "/usr/local/lib/python3.10/site-packages/django/db/models/sql/compiler.py", line 1823, in execute_sql
    cursor.execute(sql, params)
  File "/usr/local/lib/python3.10/site-packages/django/db/backends/utils.py", line 122, in execute
    return super().execute(sql, params)
  File "/usr/local/lib/python3.10/site-packages/django/db/backends/utils.py", line 79, in execute
    return self._execute_with_wrappers(
  File "/usr/local/lib/python3.10/site-packages/django/db/backends/utils.py", line 92, in _execute_with_wrappers
    return executor(sql, params, many, context)
  File "/usr/local/lib/python3.10/site-packages/django/db/backends/utils.py", line 100, in _execute
    with self.db.wrap_database_errors:
  File "/usr/local/lib/python3.10/site-packages/django/db/utils.py", line 91, in __exit__
    raise dj_exc_value.with_traceback(traceback) from exc_value
  File "/usr/local/lib/python3.10/site-packages/django/db/backends/utils.py", line 105, in _execute
    return self.cursor.execute(sql, params)
  File "/usr/local/lib/python3.10/site-packages/django/db/backends/mysql/base.py", line 76, in execute
    return self.cursor.execute(query, args)
  File "/usr/local/lib/python3.10/site-packages/MySQLdb/cursors.py", line 179, in execute
    res = self._query(mogrified_query)
  File "/usr/local/lib/python3.10/site-packages/MySQLdb/cursors.py", line 330, in _query
    db.query(q)
  File "/usr/local/lib/python3.10/site-packages/MySQLdb/connections.py", line 261, in query
    _mysql.connection.query(self, query)
django.db.utils.OperationalError: (1054, "Unknown column 'event_function' in 'field list'")


2024-06-22 09:25:53.984631+00:00: invalid syntax (<string>, line 1)
Traceback (most recent call last):
  File "/home/user/sources/event_schedules/models.py", line 124, in doevent
    return event.first().doevent()
  File "/home/user/sources/event_schedules/models.py", line 105, in doevent
    raise e
  File "/home/user/sources/event_schedules/models.py", line 97, in doevent
    exec("import {}".format(self.event_function.split(".")[0]))
  File "<string>", line 1
    import 
           ^
SyntaxError: invalid syntax


2024-06-23 12:21:35.113473+00:00: Replacement index 0 out of range for positional args tuple
Traceback (most recent call last):
  File "/home/user/sources/event_schedules/models.py", line 131, in doevent
    return event.first().doevent()
  File "/home/user/sources/event_schedules/models.py", line 112, in doevent
    raise e
  File "/home/user/sources/event_schedules/models.py", line 104, in doevent
    exec("import {}".format())
IndexError: Replacement index 0 out of range for positional args tuple


2024-06-23 12:22:12.084380+00:00: Replacement index 0 out of range for positional args tuple
Traceback (most recent call last):
  File "/home/user/sources/event_schedules/models.py", line 131, in doevent
    return event.first().doevent()
  File "/home/user/sources/event_schedules/models.py", line 112, in doevent
    raise e
  File "/home/user/sources/event_schedules/models.py", line 104, in doevent
    exec("import {}".format())
IndexError: Replacement index 0 out of range for positional args tuple


2024-06-23 12:22:38.021948+00:00: Replacement index 0 out of range for positional args tuple
Traceback (most recent call last):
  File "/home/user/sources/event_schedules/models.py", line 131, in doevent
    return event.first().doevent()
  File "/home/user/sources/event_schedules/models.py", line 112, in doevent
    raise e
  File "/home/user/sources/event_schedules/models.py", line 104, in doevent
    exec("import {}".format())
IndexError: Replacement index 0 out of range for positional args tuple


2024-06-23 12:23:25.784144+00:00: invalid syntax (<string>, line 1)
Traceback (most recent call last):
  File "/home/user/sources/event_schedules/models.py", line 131, in doevent
    return event.first().doevent()
  File "/home/user/sources/event_schedules/models.py", line 112, in doevent
    raise e
  File "/home/user/sources/event_schedules/models.py", line 104, in doevent
    exec("import {}")
  File "<string>", line 1
    import {}
           ^
SyntaxError: invalid syntax


2024-07-05 05:52:24.305032+00:00: No module named 'events'
Traceback (most recent call last):
  File "/home/user/sources/apps/event_schedules/models.py", line 129, in doevent
    return event.first().doevent()
  File "/home/user/sources/apps/event_schedules/models.py", line 110, in doevent
    raise e
  File "/home/user/sources/apps/event_schedules/models.py", line 101, in doevent
    module = importlib.import_module("events")
  File "/usr/local/lib/python3.10/importlib/__init__.py", line 126, in import_module
    return _bootstrap._gcd_import(name[level:], package, level)
  File "<frozen importlib._bootstrap>", line 1050, in _gcd_import
  File "<frozen importlib._bootstrap>", line 1027, in _find_and_load
  File "<frozen importlib._bootstrap>", line 1004, in _find_and_load_unlocked
ModuleNotFoundError: No module named 'events'


2024-07-05 05:53:13.255146+00:00: the 'package' argument is required to perform a relative import for '.events'
Traceback (most recent call last):
  File "/home/user/sources/apps/event_schedules/models.py", line 129, in doevent
    return event.first().doevent()
  File "/home/user/sources/apps/event_schedules/models.py", line 110, in doevent
    raise e
  File "/home/user/sources/apps/event_schedules/models.py", line 101, in doevent
    module = importlib.import_module(".events")
  File "/usr/local/lib/python3.10/importlib/__init__.py", line 121, in import_module
    raise TypeError(msg.format(name))
TypeError: the 'package' argument is required to perform a relative import for '.events'


2024-07-05 05:53:35.408973+00:00: module 'apps.event_schedules.events' has no attribute 'test_event'
Traceback (most recent call last):
  File "/home/user/sources/apps/event_schedules/models.py", line 129, in doevent
    return event.first().doevent()
  File "/home/user/sources/apps/event_schedules/models.py", line 110, in doevent
    raise e
  File "/home/user/sources/apps/event_schedules/models.py", line 102, in doevent
    event = getattr(module, self.event_function)
AttributeError: module 'apps.event_schedules.events' has no attribute 'test_event'


2024-07-05 05:53:56.352590+00:00: module 'apps.event_schedules.events' has no attribute 'test_event'
Traceback (most recent call last):
  File "/home/user/sources/apps/event_schedules/models.py", line 129, in doevent
    return event.first().doevent()
  File "/home/user/sources/apps/event_schedules/models.py", line 110, in doevent
    raise e
  File "/home/user/sources/apps/event_schedules/models.py", line 102, in doevent
    event = getattr(module, self.event_function)
AttributeError: module 'apps.event_schedules.events' has no attribute 'test_event'


2024-07-05 07:17:11.677037+00:00: 'Schedule' object has no attribute 'title'
Traceback (most recent call last):
  File "/home/user/sources/apps/event_schedules/models.py", line 140, in doevent
    return event.first().doevent()
  File "/home/user/sources/apps/event_schedules/models.py", line 123, in doevent
    event_history.save()
  File "/home/user/sources/apps/event_schedules/models.py", line 24, in save
    "schedule: " + str(self.schedule.title),
AttributeError: 'Schedule' object has no attribute 'title'


2024-07-05 07:17:47.047769+00:00: 'Schedule' object has no attribute 'title'
Traceback (most recent call last):
  File "/home/user/sources/apps/event_schedules/models.py", line 140, in doevent
    return event.first().doevent()
  File "/home/user/sources/apps/event_schedules/models.py", line 123, in doevent
    event_history.save()
  File "/home/user/sources/apps/event_schedules/models.py", line 24, in save
    "schedule: " + str(self.schedule.title),
AttributeError: 'Schedule' object has no attribute 'title'


2024-07-05 07:31:17.472533+00:00: 'NoneType' object has no attribute 'SCHEDULE_STR'
Traceback (most recent call last):
  File "/home/user/sources/apps/event_schedules/models.py", line 146, in doevent
    return event.first().doevent()
  File "/home/user/sources/apps/event_schedules/models.py", line 97, in doevent
    schedule_str_default = event_function.SCHEDULE_STR
AttributeError: 'NoneType' object has no attribute 'SCHEDULE_STR'


2024-07-05 07:33:00.978334+00:00: 'NoneType' object has no attribute 'SCHEDULE_STR'
Traceback (most recent call last):
  File "/home/user/sources/apps/event_schedules/models.py", line 148, in doevent
    return event.first().doevent()
  File "/home/user/sources/apps/event_schedules/models.py", line 97, in doevent
    schedule_str_default = event_function.SCHEDULE_STR
AttributeError: 'NoneType' object has no attribute 'SCHEDULE_STR'


2024-07-05 07:33:26.459844+00:00: 'NoneType' object has no attribute 'SCHEDULE_STR'
Traceback (most recent call last):
  File "/home/user/sources/apps/event_schedules/models.py", line 148, in doevent
    return event.first().doevent()
  File "/home/user/sources/apps/event_schedules/models.py", line 97, in doevent
    schedule_str_default = event_function.SCHEDULE_STR
AttributeError: 'NoneType' object has no attribute 'SCHEDULE_STR'


2024-07-05 07:34:45.101634+00:00: 'NoneType' object has no attribute 'SCHEDULE_STR'
Traceback (most recent call last):
  File "/home/user/sources/apps/event_schedules/models.py", line 148, in doevent
    return event.first().doevent()
  File "/home/user/sources/apps/event_schedules/models.py", line 97, in doevent
    schedule_str_default = event_function.SCHEDULE_STR
AttributeError: 'NoneType' object has no attribute 'SCHEDULE_STR'


2024-07-05 09:18:25.553116+00:00: type object 'Pages' has no attribute 'extract_raceids'
Traceback (most recent call last):
  File "/home/user/sources/apps/event_schedules/models.py", line 145, in doevent
    return event.first().doevent()
  File "/home/user/sources/apps/event_schedules/models.py", line 112, in doevent
    raise e
  File "/home/user/sources/apps/event_schedules/models.py", line 105, in doevent
    event_function.main()
  File "/home/user/sources/apps/event_schedules/events/new_raceids.py", line 5, in main
    print(Pages.extract_raceids())
AttributeError: type object 'Pages' has no attribute 'extract_raceids'


2024-07-05 09:19:20.509211+00:00: type object 'Pages' has no attribute 'extract_raceids'
Traceback (most recent call last):
  File "/home/user/sources/apps/event_schedules/models.py", line 145, in doevent
    return event.first().doevent()
  File "/home/user/sources/apps/event_schedules/models.py", line 112, in doevent
    raise e
  File "/home/user/sources/apps/event_schedules/models.py", line 105, in doevent
    event_function.main()
  File "/home/user/sources/apps/event_schedules/events/new_raceids.py", line 5, in main
    print(Pages.extract_raceids())
AttributeError: type object 'Pages' has no attribute 'extract_raceids'


2024-07-05 09:20:34.663272+00:00: type object 'Page' has no attribute 'Page'
Traceback (most recent call last):
  File "/home/user/sources/apps/event_schedules/models.py", line 145, in doevent
    return event.first().doevent()
  File "/home/user/sources/apps/event_schedules/models.py", line 112, in doevent
    raise e
  File "/home/user/sources/apps/event_schedules/models.py", line 105, in doevent
    event_function.main()
  File "/home/user/sources/apps/event_schedules/events/new_raceids.py", line 5, in main
    print(Page.Page.extract_raceids())
AttributeError: type object 'Page' has no attribute 'Page'


2024-07-05 09:41:54.337226+00:00: <urlopen error nar.netkeiba.comには追い切りページがありません。>
Traceback (most recent call last):
  File "/home/user/sources/apps/event_schedules/models.py", line 145, in doevent
    return event.first().doevent()
  File "/home/user/sources/apps/event_schedules/models.py", line 112, in doevent
    raise e
  File "/home/user/sources/apps/event_schedules/models.py", line 105, in doevent
    event_function.main()
  File "/home/user/sources/apps/event_schedules/events/new_page_with_login.py", line 8, in main
    models[0].new_page()
  File "/home/user/sources/apps/web_netkeiba_pagesources/models.py", line 109, in new_page
    page.update_html()
  File "/home/user/sources/apps/web_netkeiba_pagesources/models.py", line 22, in wrapper
    new_kwargs = {"url": self_or_cls.url}
  File "/home/user/sources/apps/web_netkeiba_pagesources/models.py", line 215, in url
    raise URLError("nar.netkeiba.comには追い切りページがありません。")
urllib.error.URLError: <urlopen error nar.netkeiba.comには追い切りページがありません。>


2024-07-05 09:45:25.026614+00:00: Message: invalid argument
  (Session info: chrome=125.0.6422.76)
Stacktrace:
#0 0x5579fc63fe9a <unknown>
#1 0x5579fc3292a1 <unknown>
#2 0x5579fc30f973 <unknown>
#3 0x5579fc30e1b8 <unknown>
#4 0x5579fc30e83a <unknown>
#5 0x5579fc32bea7 <unknown>
#6 0x5579fc3b7ed5 <unknown>
#7 0x5579fc3984b2 <unknown>
#8 0x5579fc3b72cc <unknown>
#9 0x5579fc398253 <unknown>
#10 0x5579fc3681c7 <unknown>
#11 0x5579fc368b3e <unknown>
#12 0x5579fc6062db <unknown>
#13 0x5579fc60a387 <unknown>
#14 0x5579fc5f2e0e <unknown>
#15 0x5579fc60ae52 <unknown>
#16 0x5579fc5d77af <unknown>
#17 0x5579fc62f188 <unknown>
#18 0x5579fc62f35b <unknown>
#19 0x5579fc63efcc <unknown>
#20 0x7efdc0e59ac3 <unknown>

Traceback (most recent call last):
  File "/home/user/sources/apps/event_schedules/models.py", line 145, in doevent
    return event.first().doevent()
  File "/home/user/sources/apps/event_schedules/models.py", line 112, in doevent
    raise e
  File "/home/user/sources/apps/event_schedules/models.py", line 105, in doevent
    event_function.main()
  File "/home/user/sources/apps/event_schedules/events/new_page_with_login.py", line 8, in main
    models[0].new_page()
  File "/home/user/sources/apps/web_netkeiba_pagesources/models.py", line 111, in new_page
    page.update_html()
  File "/home/user/sources/apps/web_netkeiba_pagesources/models.py", line 33, in wrapper
    with WebDriver(**new_kwargs) as driver:
  File "/home/user/sources/apps/web_controller/apps.py", line 64, in __init__
    self.__cookie_init(domain)
  File "/home/user/sources/apps/web_controller/apps.py", line 72, in __cookie_init
    self.driver.get(domain)
  File "/usr/local/lib/python3.10/site-packages/selenium/webdriver/remote/webdriver.py", line 363, in get
    self.execute(Command.GET, {"url": url})
  File "/usr/local/lib/python3.10/site-packages/selenium/webdriver/remote/webdriver.py", line 354, in execute
    self.error_handler.check_response(response)
  File "/usr/local/lib/python3.10/site-packages/selenium/webdriver/remote/errorhandler.py", line 229, in check_response
    raise exception_class(message, screen, stacktrace)
selenium.common.exceptions.InvalidArgumentException: Message: invalid argument
  (Session info: chrome=125.0.6422.76)
Stacktrace:
#0 0x5579fc63fe9a <unknown>
#1 0x5579fc3292a1 <unknown>
#2 0x5579fc30f973 <unknown>
#3 0x5579fc30e1b8 <unknown>
#4 0x5579fc30e83a <unknown>
#5 0x5579fc32bea7 <unknown>
#6 0x5579fc3b7ed5 <unknown>
#7 0x5579fc3984b2 <unknown>
#8 0x5579fc3b72cc <unknown>
#9 0x5579fc398253 <unknown>
#10 0x5579fc3681c7 <unknown>
#11 0x5579fc368b3e <unknown>
#12 0x5579fc6062db <unknown>
#13 0x5579fc60a387 <unknown>
#14 0x5579fc5f2e0e <unknown>
#15 0x5579fc60ae52 <unknown>
#16 0x5579fc5d77af <unknown>
#17 0x5579fc62f188 <unknown>
#18 0x5579fc62f35b <unknown>
#19 0x5579fc63efcc <unknown>
#20 0x7efdc0e59ac3 <unknown>



2024-07-05 09:47:54.987594+00:00: Message: invalid argument
  (Session info: chrome=125.0.6422.76)
Stacktrace:
#0 0x55c9efd9ee9a <unknown>
#1 0x55c9efa882a1 <unknown>
#2 0x55c9efa6e973 <unknown>
#3 0x55c9efa6d1b8 <unknown>
#4 0x55c9efa6d83a <unknown>
#5 0x55c9efa8aea7 <unknown>
#6 0x55c9efb16ed5 <unknown>
#7 0x55c9efaf74b2 <unknown>
#8 0x55c9efb162cc <unknown>
#9 0x55c9efaf7253 <unknown>
#10 0x55c9efac71c7 <unknown>
#11 0x55c9efac7b3e <unknown>
#12 0x55c9efd652db <unknown>
#13 0x55c9efd69387 <unknown>
#14 0x55c9efd51e0e <unknown>
#15 0x55c9efd69e52 <unknown>
#16 0x55c9efd367af <unknown>
#17 0x55c9efd8e188 <unknown>
#18 0x55c9efd8e35b <unknown>
#19 0x55c9efd9dfcc <unknown>
#20 0x7f37462abac3 <unknown>

Traceback (most recent call last):
  File "/home/user/sources/apps/event_schedules/models.py", line 145, in doevent
    return event.first().doevent()
  File "/home/user/sources/apps/event_schedules/models.py", line 112, in doevent
    raise e
  File "/home/user/sources/apps/event_schedules/models.py", line 105, in doevent
    event_function.main()
  File "/home/user/sources/apps/event_schedules/events/new_page_with_login.py", line 8, in main
    models[0].new_page()
  File "/home/user/sources/apps/web_netkeiba_pagesources/models.py", line 111, in new_page
    page.update_html()
  File "/home/user/sources/apps/web_netkeiba_pagesources/models.py", line 33, in wrapper
    with WebDriver(**new_kwargs) as driver:
  File "/home/user/sources/apps/web_controller/apps.py", line 64, in __init__
    self.__cookie_init(domain)
  File "/home/user/sources/apps/web_controller/apps.py", line 72, in __cookie_init
    self.driver.get(domain)
  File "/usr/local/lib/python3.10/site-packages/selenium/webdriver/remote/webdriver.py", line 363, in get
    self.execute(Command.GET, {"url": url})
  File "/usr/local/lib/python3.10/site-packages/selenium/webdriver/remote/webdriver.py", line 354, in execute
    self.error_handler.check_response(response)
  File "/usr/local/lib/python3.10/site-packages/selenium/webdriver/remote/errorhandler.py", line 229, in check_response
    raise exception_class(message, screen, stacktrace)
selenium.common.exceptions.InvalidArgumentException: Message: invalid argument
  (Session info: chrome=125.0.6422.76)
Stacktrace:
#0 0x55c9efd9ee9a <unknown>
#1 0x55c9efa882a1 <unknown>
#2 0x55c9efa6e973 <unknown>
#3 0x55c9efa6d1b8 <unknown>
#4 0x55c9efa6d83a <unknown>
#5 0x55c9efa8aea7 <unknown>
#6 0x55c9efb16ed5 <unknown>
#7 0x55c9efaf74b2 <unknown>
#8 0x55c9efb162cc <unknown>
#9 0x55c9efaf7253 <unknown>
#10 0x55c9efac71c7 <unknown>
#11 0x55c9efac7b3e <unknown>
#12 0x55c9efd652db <unknown>
#13 0x55c9efd69387 <unknown>
#14 0x55c9efd51e0e <unknown>
#15 0x55c9efd69e52 <unknown>
#16 0x55c9efd367af <unknown>
#17 0x55c9efd8e188 <unknown>
#18 0x55c9efd8e35b <unknown>
#19 0x55c9efd9dfcc <unknown>
#20 0x7f37462abac3 <unknown>



2024-07-05 09:52:55.318679+00:00: Message: invalid argument
  (Session info: chrome=125.0.6422.76)
Stacktrace:
#0 0x55bc0dc11e9a <unknown>
#1 0x55bc0d8fb2a1 <unknown>
#2 0x55bc0d8e1973 <unknown>
#3 0x55bc0d8e01b8 <unknown>
#4 0x55bc0d8e083a <unknown>
#5 0x55bc0d8fdea7 <unknown>
#6 0x55bc0d989ed5 <unknown>
#7 0x55bc0d96a4b2 <unknown>
#8 0x55bc0d9892cc <unknown>
#9 0x55bc0d96a253 <unknown>
#10 0x55bc0d93a1c7 <unknown>
#11 0x55bc0d93ab3e <unknown>
#12 0x55bc0dbd82db <unknown>
#13 0x55bc0dbdc387 <unknown>
#14 0x55bc0dbc4e0e <unknown>
#15 0x55bc0dbdce52 <unknown>
#16 0x55bc0dba97af <unknown>
#17 0x55bc0dc01188 <unknown>
#18 0x55bc0dc0135b <unknown>
#19 0x55bc0dc10fcc <unknown>
#20 0x7fdfc5deeac3 <unknown>

Traceback (most recent call last):
  File "/home/user/sources/apps/event_schedules/models.py", line 145, in doevent
    return event.first().doevent()
  File "/home/user/sources/apps/event_schedules/models.py", line 112, in doevent
    raise e
  File "/home/user/sources/apps/event_schedules/models.py", line 105, in doevent
    event_function.main()
  File "/home/user/sources/apps/event_schedules/events/new_page_with_login.py", line 8, in main
    models[0].new_page()
  File "/home/user/sources/apps/web_netkeiba_pagesources/models.py", line 113, in new_page
    page.update_html()
  File "/home/user/sources/apps/web_netkeiba_pagesources/models.py", line 33, in wrapper
    with WebDriver(**new_kwargs) as driver:
  File "/home/user/sources/apps/web_controller/apps.py", line 64, in __init__
    self.__cookie_init(domain)
  File "/home/user/sources/apps/web_controller/apps.py", line 72, in __cookie_init
    self.driver.get(domain)
  File "/usr/local/lib/python3.10/site-packages/selenium/webdriver/remote/webdriver.py", line 363, in get
    self.execute(Command.GET, {"url": url})
  File "/usr/local/lib/python3.10/site-packages/selenium/webdriver/remote/webdriver.py", line 354, in execute
    self.error_handler.check_response(response)
  File "/usr/local/lib/python3.10/site-packages/selenium/webdriver/remote/errorhandler.py", line 229, in check_response
    raise exception_class(message, screen, stacktrace)
selenium.common.exceptions.InvalidArgumentException: Message: invalid argument
  (Session info: chrome=125.0.6422.76)
Stacktrace:
#0 0x55bc0dc11e9a <unknown>
#1 0x55bc0d8fb2a1 <unknown>
#2 0x55bc0d8e1973 <unknown>
#3 0x55bc0d8e01b8 <unknown>
#4 0x55bc0d8e083a <unknown>
#5 0x55bc0d8fdea7 <unknown>
#6 0x55bc0d989ed5 <unknown>
#7 0x55bc0d96a4b2 <unknown>
#8 0x55bc0d9892cc <unknown>
#9 0x55bc0d96a253 <unknown>
#10 0x55bc0d93a1c7 <unknown>
#11 0x55bc0d93ab3e <unknown>
#12 0x55bc0dbd82db <unknown>
#13 0x55bc0dbdc387 <unknown>
#14 0x55bc0dbc4e0e <unknown>
#15 0x55bc0dbdce52 <unknown>
#16 0x55bc0dba97af <unknown>
#17 0x55bc0dc01188 <unknown>
#18 0x55bc0dc0135b <unknown>
#19 0x55bc0dc10fcc <unknown>
#20 0x7fdfc5deeac3 <unknown>



2024-07-05 09:59:25.139829+00:00: <urlopen error nar.netkeiba.comには追い切りページがありません。>
Traceback (most recent call last):
  File "/home/user/sources/apps/event_schedules/models.py", line 145, in doevent
    return event.first().doevent()
  File "/home/user/sources/apps/event_schedules/models.py", line 112, in doevent
    raise e
  File "/home/user/sources/apps/event_schedules/models.py", line 105, in doevent
    event_function.main()
  File "/home/user/sources/apps/event_schedules/events/new_page_with_login.py", line 8, in main
    models[0].new_page()
  File "/home/user/sources/apps/web_netkeiba_pagesources/models.py", line 112, in new_page
    page.update_html()
  File "/home/user/sources/apps/web_netkeiba_pagesources/models.py", line 25, in wrapper
    raise e
  File "/home/user/sources/apps/web_netkeiba_pagesources/models.py", line 23, in wrapper
    new_kwargs = {"url": self_or_cls.url}
  File "/home/user/sources/apps/web_netkeiba_pagesources/models.py", line 218, in url
    raise URLError("nar.netkeiba.comには追い切りページがありません。")
urllib.error.URLError: <urlopen error nar.netkeiba.comには追い切りページがありません。>


2024-07-05 10:00:37.901877+00:00: 'str' object has no attribute 'start_with'
Traceback (most recent call last):
  File "/home/user/sources/apps/event_schedules/models.py", line 145, in doevent
    return event.first().doevent()
  File "/home/user/sources/apps/event_schedules/models.py", line 112, in doevent
    raise e
  File "/home/user/sources/apps/event_schedules/models.py", line 105, in doevent
    event_function.main()
  File "/home/user/sources/apps/event_schedules/events/new_page_with_login.py", line 8, in main
    models[0].new_page()
  File "/home/user/sources/apps/web_netkeiba_pagesources/models.py", line 110, in new_page
    page.update_html()
  File "/home/user/sources/apps/web_netkeiba_pagesources/models.py", line 36, in wrapper
    return method(self_or_cls, *args, **kwargs)
  File "/home/user/sources/apps/web_netkeiba_pagesources/models.py", line 86, in update_html
    if not driver.current_url.start_with(self.url):
AttributeError: 'str' object has no attribute 'start_with'


2024-07-05 10:01:34.773925+00:00: 'str' object has no attribute 'starts_with'
Traceback (most recent call last):
  File "/home/user/sources/apps/event_schedules/models.py", line 145, in doevent
    return event.first().doevent()
  File "/home/user/sources/apps/event_schedules/models.py", line 112, in doevent
    raise e
  File "/home/user/sources/apps/event_schedules/models.py", line 105, in doevent
    event_function.main()
  File "/home/user/sources/apps/event_schedules/events/new_page_with_login.py", line 8, in main
    models[0].new_page()
  File "/home/user/sources/apps/web_netkeiba_pagesources/models.py", line 110, in new_page
    page.update_html()
  File "/home/user/sources/apps/web_netkeiba_pagesources/models.py", line 36, in wrapper
    return method(self_or_cls, *args, **kwargs)
  File "/home/user/sources/apps/web_netkeiba_pagesources/models.py", line 86, in update_html
    if not driver.current_url.starts_with(self.url):
AttributeError: 'str' object has no attribute 'starts_with'


2024-07-05 10:01:47.425803+00:00: 'str' object has no attribute 'starts_with'
Traceback (most recent call last):
  File "/home/user/sources/apps/event_schedules/models.py", line 145, in doevent
    return event.first().doevent()
  File "/home/user/sources/apps/event_schedules/models.py", line 112, in doevent
    raise e
  File "/home/user/sources/apps/event_schedules/models.py", line 105, in doevent
    event_function.main()
  File "/home/user/sources/apps/event_schedules/events/new_page_with_login.py", line 8, in main
    models[0].new_page()
  File "/home/user/sources/apps/web_netkeiba_pagesources/models.py", line 110, in new_page
    page.update_html()
  File "/home/user/sources/apps/web_netkeiba_pagesources/models.py", line 36, in wrapper
    return method(self_or_cls, *args, **kwargs)
  File "/home/user/sources/apps/web_netkeiba_pagesources/models.py", line 86, in update_html
    if not driver.current_url.starts_with(self.url):
AttributeError: 'str' object has no attribute 'starts_with'


2024-07-14 10:22:22.101493+00:00: Message: invalid cookie domain
  (Session info: chrome=125.0.6422.76)
Stacktrace:
#0 0x55c137381e9a <unknown>
#1 0x55c13706b2a1 <unknown>
#2 0x55c13710c04b <unknown>
#3 0x55c1370da4b2 <unknown>
#4 0x55c1370f92cc <unknown>
#5 0x55c1370da253 <unknown>
#6 0x55c1370aa1c7 <unknown>
#7 0x55c1370aab3e <unknown>
#8 0x55c1373482db <unknown>
#9 0x55c13734c387 <unknown>
#10 0x55c137334e0e <unknown>
#11 0x55c13734ce52 <unknown>
#12 0x55c1373197af <unknown>
#13 0x55c137371188 <unknown>
#14 0x55c13737135b <unknown>
#15 0x55c137380fcc <unknown>
#16 0x7f22be942ac3 <unknown>

Traceback (most recent call last):
  File "/home/user/sources/apps/event_schedules/models.py", line 145, in doevent
    return event.first().doevent()
  File "/home/user/sources/apps/event_schedules/models.py", line 112, in doevent
    raise e
  File "/home/user/sources/apps/event_schedules/models.py", line 105, in doevent
    event_function.main()
  File "/home/user/sources/apps/event_schedules/events/new_page_with_login.py", line 8, in main
    models[0].new_page()
  File "/home/user/sources/apps/web_netkeiba_pagesources/models.py", line 111, in new_page
    page.update_html()
  File "/home/user/sources/apps/web_netkeiba_pagesources/models.py", line 34, in wrapper
    with WebDriver(**new_kwargs) as driver:
  File "/home/user/sources/apps/web_controller/apps.py", line 64, in __init__
    self.__cookie_init(domain)
  File "/home/user/sources/apps/web_controller/apps.py", line 82, in __cookie_init
    self.driver.add_cookie(cookie)
  File "/usr/local/lib/python3.10/site-packages/selenium/webdriver/remote/webdriver.py", line 641, in add_cookie
    self.execute(Command.ADD_COOKIE, {"cookie": cookie_dict})
  File "/usr/local/lib/python3.10/site-packages/selenium/webdriver/remote/webdriver.py", line 354, in execute
    self.error_handler.check_response(response)
  File "/usr/local/lib/python3.10/site-packages/selenium/webdriver/remote/errorhandler.py", line 229, in check_response
    raise exception_class(message, screen, stacktrace)
selenium.common.exceptions.InvalidCookieDomainException: Message: invalid cookie domain
  (Session info: chrome=125.0.6422.76)
Stacktrace:
#0 0x55c137381e9a <unknown>
#1 0x55c13706b2a1 <unknown>
#2 0x55c13710c04b <unknown>
#3 0x55c1370da4b2 <unknown>
#4 0x55c1370f92cc <unknown>
#5 0x55c1370da253 <unknown>
#6 0x55c1370aa1c7 <unknown>
#7 0x55c1370aab3e <unknown>
#8 0x55c1373482db <unknown>
#9 0x55c13734c387 <unknown>
#10 0x55c137334e0e <unknown>
#11 0x55c13734ce52 <unknown>
#12 0x55c1373197af <unknown>
#13 0x55c137371188 <unknown>
#14 0x55c13737135b <unknown>
#15 0x55c137380fcc <unknown>
#16 0x7f22be942ac3 <unknown>



2024-07-15 09:13:04.804518+00:00: Message: invalid cookie domain
  (Session info: chrome=125.0.6422.76)
Stacktrace:
#0 0x5652a82a8e9a <unknown>
#1 0x5652a7f922a1 <unknown>
#2 0x5652a803304b <unknown>
#3 0x5652a80014b2 <unknown>
#4 0x5652a80202cc <unknown>
#5 0x5652a8001253 <unknown>
#6 0x5652a7fd11c7 <unknown>
#7 0x5652a7fd1b3e <unknown>
#8 0x5652a826f2db <unknown>
#9 0x5652a8273387 <unknown>
#10 0x5652a825be0e <unknown>
#11 0x5652a8273e52 <unknown>
#12 0x5652a82407af <unknown>
#13 0x5652a8298188 <unknown>
#14 0x5652a829835b <unknown>
#15 0x5652a82a7fcc <unknown>
#16 0x7f24ea696ac3 <unknown>

Traceback (most recent call last):
  File "/home/user/sources/apps/event_schedules/models.py", line 145, in doevent
    return event.first().doevent()
  File "/home/user/sources/apps/event_schedules/models.py", line 112, in doevent
    raise e
  File "/home/user/sources/apps/event_schedules/models.py", line 105, in doevent
    event_function.main()
  File "/home/user/sources/apps/event_schedules/events/new_page_with_login.py", line 8, in main
    models[0].new_page()
  File "/home/user/sources/apps/web_netkeiba_pagesources/models.py", line 115, in new_page
    page.update_html()
  File "/home/user/sources/apps/web_netkeiba_pagesources/models.py", line 34, in wrapper
    with WebDriver(**new_kwargs) as driver:
  File "/home/user/sources/apps/web_controller/apps.py", line 64, in __init__
    self.__cookie_init(domain)
  File "/home/user/sources/apps/web_controller/apps.py", line 83, in __cookie_init
    self.driver.add_cookie(cookie)
  File "/usr/local/lib/python3.10/site-packages/selenium/webdriver/remote/webdriver.py", line 641, in add_cookie
    self.execute(Command.ADD_COOKIE, {"cookie": cookie_dict})
  File "/usr/local/lib/python3.10/site-packages/selenium/webdriver/remote/webdriver.py", line 354, in execute
    self.error_handler.check_response(response)
  File "/usr/local/lib/python3.10/site-packages/selenium/webdriver/remote/errorhandler.py", line 229, in check_response
    raise exception_class(message, screen, stacktrace)
selenium.common.exceptions.InvalidCookieDomainException: Message: invalid cookie domain
  (Session info: chrome=125.0.6422.76)
Stacktrace:
#0 0x5652a82a8e9a <unknown>
#1 0x5652a7f922a1 <unknown>
#2 0x5652a803304b <unknown>
#3 0x5652a80014b2 <unknown>
#4 0x5652a80202cc <unknown>
#5 0x5652a8001253 <unknown>
#6 0x5652a7fd11c7 <unknown>
#7 0x5652a7fd1b3e <unknown>
#8 0x5652a826f2db <unknown>
#9 0x5652a8273387 <unknown>
#10 0x5652a825be0e <unknown>
#11 0x5652a8273e52 <unknown>
#12 0x5652a82407af <unknown>
#13 0x5652a8298188 <unknown>
#14 0x5652a829835b <unknown>
#15 0x5652a82a7fcc <unknown>
#16 0x7f24ea696ac3 <unknown>



2024-07-15 09:20:05.254586+00:00: Message: invalid cookie domain
  (Session info: chrome=125.0.6422.76)
Stacktrace:
#0 0x5597863b0e9a <unknown>
#1 0x55978609a2a1 <unknown>
#2 0x55978613b04b <unknown>
#3 0x5597861094b2 <unknown>
#4 0x5597861282cc <unknown>
#5 0x559786109253 <unknown>
#6 0x5597860d91c7 <unknown>
#7 0x5597860d9b3e <unknown>
#8 0x5597863772db <unknown>
#9 0x55978637b387 <unknown>
#10 0x559786363e0e <unknown>
#11 0x55978637be52 <unknown>
#12 0x5597863487af <unknown>
#13 0x5597863a0188 <unknown>
#14 0x5597863a035b <unknown>
#15 0x5597863affcc <unknown>
#16 0x7f8cdd9cbac3 <unknown>

Traceback (most recent call last):
  File "/home/user/sources/apps/event_schedules/models.py", line 149, in doevent
    return event.first().doevent()
  File "/home/user/sources/apps/event_schedules/models.py", line 116, in doevent
    raise e
  File "/home/user/sources/apps/event_schedules/models.py", line 109, in doevent
    event_function.main()
  File "/home/user/sources/apps/event_schedules/events/new_page_with_login.py", line 8, in main
    models[0].new_page()
  File "/home/user/sources/apps/web_netkeiba_pagesources/models.py", line 115, in new_page
    page.update_html()
  File "/home/user/sources/apps/web_netkeiba_pagesources/models.py", line 34, in wrapper
    with WebDriver(**new_kwargs) as driver:
  File "/home/user/sources/apps/web_controller/apps.py", line 64, in __init__
    self.__cookie_init(domain)
  File "/home/user/sources/apps/web_controller/apps.py", line 83, in __cookie_init
    self.driver.add_cookie(cookie)
  File "/usr/local/lib/python3.10/site-packages/selenium/webdriver/remote/webdriver.py", line 641, in add_cookie
    self.execute(Command.ADD_COOKIE, {"cookie": cookie_dict})
  File "/usr/local/lib/python3.10/site-packages/selenium/webdriver/remote/webdriver.py", line 354, in execute
    self.error_handler.check_response(response)
  File "/usr/local/lib/python3.10/site-packages/selenium/webdriver/remote/errorhandler.py", line 229, in check_response
    raise exception_class(message, screen, stacktrace)
selenium.common.exceptions.InvalidCookieDomainException: Message: invalid cookie domain
  (Session info: chrome=125.0.6422.76)
Stacktrace:
#0 0x5597863b0e9a <unknown>
#1 0x55978609a2a1 <unknown>
#2 0x55978613b04b <unknown>
#3 0x5597861094b2 <unknown>
#4 0x5597861282cc <unknown>
#5 0x559786109253 <unknown>
#6 0x5597860d91c7 <unknown>
#7 0x5597860d9b3e <unknown>
#8 0x5597863772db <unknown>
#9 0x55978637b387 <unknown>
#10 0x559786363e0e <unknown>
#11 0x55978637be52 <unknown>
#12 0x5597863487af <unknown>
#13 0x5597863a0188 <unknown>
#14 0x5597863a035b <unknown>
#15 0x5597863affcc <unknown>
#16 0x7f8cdd9cbac3 <unknown>



2024-07-15 09:26:39.754002+00:00: get() returned more than one PageCategory -- it returned 2!
Traceback (most recent call last):
  File "/home/user/sources/apps/event_schedules/models.py", line 149, in doevent
    return event.first().doevent()
  File "/home/user/sources/apps/event_schedules/models.py", line 116, in doevent
    raise e
  File "/home/user/sources/apps/event_schedules/models.py", line 109, in doevent
    event_function.main()
  File "/home/user/sources/apps/event_schedules/events/new_page.py", line 8, in main
    models[0].new_page()
  File "/home/user/sources/apps/web_netkeiba_pagesources/models.py", line 115, in new_page
    page.update_html()
  File "/home/user/sources/apps/web_netkeiba_pagesources/models.py", line 36, in wrapper
    return method(self_or_cls, *args, **kwargs)
  File "/home/user/sources/apps/web_netkeiba_pagesources/models.py", line 99, in update_html
    extract_raceids(driver)
  File "/home/user/sources/apps/web_netkeiba_pagesources/models.py", line 54, in extract_raceids
    category = race_categorys.get(race_category, PageCategory.objects.get_or_create(name=race_category)[0])
  File "/usr/local/lib/python3.10/site-packages/django/db/models/manager.py", line 87, in manager_method
    return getattr(self.get_queryset(), name)(*args, **kwargs)
  File "/usr/local/lib/python3.10/site-packages/django/db/models/query.py", line 948, in get_or_create
    return self.get(**kwargs), False
  File "/usr/local/lib/python3.10/site-packages/django/db/models/query.py", line 652, in get
    raise self.model.MultipleObjectsReturned(
apps.web_netkeiba_pagesources.models.PageCategory.MultipleObjectsReturned: get() returned more than one PageCategory -- it returned 2!


(1048, "Column 'category_id' cannot be null")
Traceback (most recent call last):
  File "/usr/local/lib/python3.10/site-packages/django/db/backends/utils.py", line 105, in _execute
    return self.cursor.execute(sql, params)
  File "/usr/local/lib/python3.10/site-packages/django/db/backends/mysql/base.py", line 76, in execute
    return self.cursor.execute(query, args)
  File "/usr/local/lib/python3.10/site-packages/MySQLdb/cursors.py", line 179, in execute
    res = self._query(mogrified_query)
  File "/usr/local/lib/python3.10/site-packages/MySQLdb/cursors.py", line 330, in _query
    db.query(q)
  File "/usr/local/lib/python3.10/site-packages/MySQLdb/connections.py", line 261, in query
    _mysql.connection.query(self, query)
MySQLdb.IntegrityError: (1048, "Column 'category_id' cannot be null")

The above exception was the direct cause of the following exception:

Traceback (most recent call last):
  File "/home/user/sources/apps/web_netkeiba_pagesources/models.py", line 194, in update_html
    self.__update_html(driver)
  File "/home/user/sources/apps/web_netkeiba_pagesources/models.py", line 208, in __update_html
    self.save()
  File "/usr/local/lib/python3.10/site-packages/django/db/models/base.py", line 822, in save
    self.save_base(
  File "/usr/local/lib/python3.10/site-packages/django/db/models/base.py", line 906, in save_base
    parent_inserted = self._save_parents(
  File "/usr/local/lib/python3.10/site-packages/django/db/models/base.py", line 959, in _save_parents
    updated = self._save_table(
  File "/usr/local/lib/python3.10/site-packages/django/db/models/base.py", line 1040, in _save_table
    updated = self._do_update(
  File "/usr/local/lib/python3.10/site-packages/django/db/models/base.py", line 1105, in _do_update
    return filtered._update(values) > 0
  File "/usr/local/lib/python3.10/site-packages/django/db/models/query.py", line 1278, in _update
    return query.get_compiler(self.db).execute_sql(CURSOR)
  File "/usr/local/lib/python3.10/site-packages/django/db/models/sql/compiler.py", line 1990, in execute_sql
    cursor = super().execute_sql(result_type)
  File "/usr/local/lib/python3.10/site-packages/django/db/models/sql/compiler.py", line 1562, in execute_sql
    cursor.execute(sql, params)
  File "/usr/local/lib/python3.10/site-packages/django/db/backends/utils.py", line 79, in execute
    return self._execute_with_wrappers(
  File "/usr/local/lib/python3.10/site-packages/django/db/backends/utils.py", line 92, in _execute_with_wrappers
    return executor(sql, params, many, context)
  File "/usr/local/lib/python3.10/site-packages/django/db/backends/utils.py", line 100, in _execute
    with self.db.wrap_database_errors:
  File "/usr/local/lib/python3.10/site-packages/django/db/utils.py", line 91, in __exit__
    raise dj_exc_value.with_traceback(traceback) from exc_value
  File "/usr/local/lib/python3.10/site-packages/django/db/backends/utils.py", line 105, in _execute
    return self.cursor.execute(sql, params)
  File "/usr/local/lib/python3.10/site-packages/django/db/backends/mysql/base.py", line 76, in execute
    return self.cursor.execute(query, args)
  File "/usr/local/lib/python3.10/site-packages/MySQLdb/cursors.py", line 179, in execute
    res = self._query(mogrified_query)
  File "/usr/local/lib/python3.10/site-packages/MySQLdb/cursors.py", line 330, in _query
    db.query(q)
  File "/usr/local/lib/python3.10/site-packages/MySQLdb/connections.py", line 261, in query
    _mysql.connection.query(self, query)
django.db.utils.IntegrityError: (1048, "Column 'category_id' cannot be null")
(1048, "Column 'category_id' cannot be null")
Traceback (most recent call last):
  File "/usr/local/lib/python3.10/site-packages/django/db/backends/utils.py", line 105, in _execute
    return self.cursor.execute(sql, params)
  File "/usr/local/lib/python3.10/site-packages/django/db/backends/mysql/base.py", line 76, in execute
    return self.cursor.execute(query, args)
  File "/usr/local/lib/python3.10/site-packages/MySQLdb/cursors.py", line 179, in execute
    res = self._query(mogrified_query)
  File "/usr/local/lib/python3.10/site-packages/MySQLdb/cursors.py", line 330, in _query
    db.query(q)
  File "/usr/local/lib/python3.10/site-packages/MySQLdb/connections.py", line 261, in query
    _mysql.connection.query(self, query)
MySQLdb.IntegrityError: (1048, "Column 'category_id' cannot be null")

The above exception was the direct cause of the following exception:

Traceback (most recent call last):
  File "/home/user/sources/apps/web_netkeiba_pagesources/models.py", line 194, in update_html
    self.__update_html(driver)
  File "/home/user/sources/apps/web_netkeiba_pagesources/models.py", line 208, in __update_html
    self.save()
  File "/usr/local/lib/python3.10/site-packages/django/db/models/base.py", line 822, in save
    self.save_base(
  File "/usr/local/lib/python3.10/site-packages/django/db/models/base.py", line 906, in save_base
    parent_inserted = self._save_parents(
  File "/usr/local/lib/python3.10/site-packages/django/db/models/base.py", line 959, in _save_parents
    updated = self._save_table(
  File "/usr/local/lib/python3.10/site-packages/django/db/models/base.py", line 1040, in _save_table
    updated = self._do_update(
  File "/usr/local/lib/python3.10/site-packages/django/db/models/base.py", line 1105, in _do_update
    return filtered._update(values) > 0
  File "/usr/local/lib/python3.10/site-packages/django/db/models/query.py", line 1278, in _update
    return query.get_compiler(self.db).execute_sql(CURSOR)
  File "/usr/local/lib/python3.10/site-packages/django/db/models/sql/compiler.py", line 1990, in execute_sql
    cursor = super().execute_sql(result_type)
  File "/usr/local/lib/python3.10/site-packages/django/db/models/sql/compiler.py", line 1562, in execute_sql
    cursor.execute(sql, params)
  File "/usr/local/lib/python3.10/site-packages/django/db/backends/utils.py", line 79, in execute
    return self._execute_with_wrappers(
  File "/usr/local/lib/python3.10/site-packages/django/db/backends/utils.py", line 92, in _execute_with_wrappers
    return executor(sql, params, many, context)
  File "/usr/local/lib/python3.10/site-packages/django/db/backends/utils.py", line 100, in _execute
    with self.db.wrap_database_errors:
  File "/usr/local/lib/python3.10/site-packages/django/db/utils.py", line 91, in __exit__
    raise dj_exc_value.with_traceback(traceback) from exc_value
  File "/usr/local/lib/python3.10/site-packages/django/db/backends/utils.py", line 105, in _execute
    return self.cursor.execute(sql, params)
  File "/usr/local/lib/python3.10/site-packages/django/db/backends/mysql/base.py", line 76, in execute
    return self.cursor.execute(query, args)
  File "/usr/local/lib/python3.10/site-packages/MySQLdb/cursors.py", line 179, in execute
    res = self._query(mogrified_query)
  File "/usr/local/lib/python3.10/site-packages/MySQLdb/cursors.py", line 330, in _query
    db.query(q)
  File "/usr/local/lib/python3.10/site-packages/MySQLdb/connections.py", line 261, in query
    _mysql.connection.query(self, query)
django.db.utils.IntegrityError: (1048, "Column 'category_id' cannot be null")
(1048, "Column 'category_id' cannot be null")
Traceback (most recent call last):
  File "/usr/local/lib/python3.10/site-packages/django/db/backends/utils.py", line 105, in _execute
    return self.cursor.execute(sql, params)
  File "/usr/local/lib/python3.10/site-packages/django/db/backends/mysql/base.py", line 76, in execute
    return self.cursor.execute(query, args)
  File "/usr/local/lib/python3.10/site-packages/MySQLdb/cursors.py", line 179, in execute
    res = self._query(mogrified_query)
  File "/usr/local/lib/python3.10/site-packages/MySQLdb/cursors.py", line 330, in _query
    db.query(q)
  File "/usr/local/lib/python3.10/site-packages/MySQLdb/connections.py", line 261, in query
    _mysql.connection.query(self, query)
MySQLdb.IntegrityError: (1048, "Column 'category_id' cannot be null")

The above exception was the direct cause of the following exception:

Traceback (most recent call last):
  File "/home/user/sources/apps/web_netkeiba_pagesources/models.py", line 194, in update_html
    self.__update_html(driver)
  File "/home/user/sources/apps/web_netkeiba_pagesources/models.py", line 208, in __update_html
    self.save()
  File "/usr/local/lib/python3.10/site-packages/django/db/models/base.py", line 822, in save
    self.save_base(
  File "/usr/local/lib/python3.10/site-packages/django/db/models/base.py", line 906, in save_base
    parent_inserted = self._save_parents(
  File "/usr/local/lib/python3.10/site-packages/django/db/models/base.py", line 959, in _save_parents
    updated = self._save_table(
  File "/usr/local/lib/python3.10/site-packages/django/db/models/base.py", line 1040, in _save_table
    updated = self._do_update(
  File "/usr/local/lib/python3.10/site-packages/django/db/models/base.py", line 1105, in _do_update
    return filtered._update(values) > 0
  File "/usr/local/lib/python3.10/site-packages/django/db/models/query.py", line 1278, in _update
    return query.get_compiler(self.db).execute_sql(CURSOR)
  File "/usr/local/lib/python3.10/site-packages/django/db/models/sql/compiler.py", line 1990, in execute_sql
    cursor = super().execute_sql(result_type)
  File "/usr/local/lib/python3.10/site-packages/django/db/models/sql/compiler.py", line 1562, in execute_sql
    cursor.execute(sql, params)
  File "/usr/local/lib/python3.10/site-packages/django/db/backends/utils.py", line 122, in execute
    return super().execute(sql, params)
  File "/usr/local/lib/python3.10/site-packages/django/db/backends/utils.py", line 79, in execute
    return self._execute_with_wrappers(
  File "/usr/local/lib/python3.10/site-packages/django/db/backends/utils.py", line 92, in _execute_with_wrappers
    return executor(sql, params, many, context)
  File "/usr/local/lib/python3.10/site-packages/django/db/backends/utils.py", line 100, in _execute
    with self.db.wrap_database_errors:
  File "/usr/local/lib/python3.10/site-packages/django/db/utils.py", line 91, in __exit__
    raise dj_exc_value.with_traceback(traceback) from exc_value
  File "/usr/local/lib/python3.10/site-packages/django/db/backends/utils.py", line 105, in _execute
    return self.cursor.execute(sql, params)
  File "/usr/local/lib/python3.10/site-packages/django/db/backends/mysql/base.py", line 76, in execute
    return self.cursor.execute(query, args)
  File "/usr/local/lib/python3.10/site-packages/MySQLdb/cursors.py", line 179, in execute
    res = self._query(mogrified_query)
  File "/usr/local/lib/python3.10/site-packages/MySQLdb/cursors.py", line 330, in _query
    db.query(q)
  File "/usr/local/lib/python3.10/site-packages/MySQLdb/connections.py", line 261, in query
    _mysql.connection.query(self, query)
django.db.utils.IntegrityError: (1048, "Column 'category_id' cannot be null")
(1048, "Column 'category_id' cannot be null")
Traceback (most recent call last):
  File "/usr/local/lib/python3.10/site-packages/django/db/backends/utils.py", line 105, in _execute
    return self.cursor.execute(sql, params)
  File "/usr/local/lib/python3.10/site-packages/django/db/backends/mysql/base.py", line 76, in execute
    return self.cursor.execute(query, args)
  File "/usr/local/lib/python3.10/site-packages/MySQLdb/cursors.py", line 179, in execute
    res = self._query(mogrified_query)
  File "/usr/local/lib/python3.10/site-packages/MySQLdb/cursors.py", line 330, in _query
    db.query(q)
  File "/usr/local/lib/python3.10/site-packages/MySQLdb/connections.py", line 261, in query
    _mysql.connection.query(self, query)
MySQLdb.IntegrityError: (1048, "Column 'category_id' cannot be null")

The above exception was the direct cause of the following exception:

Traceback (most recent call last):
  File "/home/user/sources/apps/web_netkeiba_pagesources/models.py", line 194, in update_html
    self.__update_html(driver)
  File "/home/user/sources/apps/web_netkeiba_pagesources/models.py", line 208, in __update_html
    self.save()
  File "/usr/local/lib/python3.10/site-packages/django/db/models/base.py", line 822, in save
    self.save_base(
  File "/usr/local/lib/python3.10/site-packages/django/db/models/base.py", line 906, in save_base
    parent_inserted = self._save_parents(
  File "/usr/local/lib/python3.10/site-packages/django/db/models/base.py", line 959, in _save_parents
    updated = self._save_table(
  File "/usr/local/lib/python3.10/site-packages/django/db/models/base.py", line 1040, in _save_table
    updated = self._do_update(
  File "/usr/local/lib/python3.10/site-packages/django/db/models/base.py", line 1105, in _do_update
    return filtered._update(values) > 0
  File "/usr/local/lib/python3.10/site-packages/django/db/models/query.py", line 1278, in _update
    return query.get_compiler(self.db).execute_sql(CURSOR)
  File "/usr/local/lib/python3.10/site-packages/django/db/models/sql/compiler.py", line 1990, in execute_sql
    cursor = super().execute_sql(result_type)
  File "/usr/local/lib/python3.10/site-packages/django/db/models/sql/compiler.py", line 1562, in execute_sql
    cursor.execute(sql, params)
  File "/usr/local/lib/python3.10/site-packages/django/db/backends/utils.py", line 122, in execute
    return super().execute(sql, params)
  File "/usr/local/lib/python3.10/site-packages/django/db/backends/utils.py", line 79, in execute
    return self._execute_with_wrappers(
  File "/usr/local/lib/python3.10/site-packages/django/db/backends/utils.py", line 92, in _execute_with_wrappers
    return executor(sql, params, many, context)
  File "/usr/local/lib/python3.10/site-packages/django/db/backends/utils.py", line 100, in _execute
    with self.db.wrap_database_errors:
  File "/usr/local/lib/python3.10/site-packages/django/db/utils.py", line 91, in __exit__
    raise dj_exc_value.with_traceback(traceback) from exc_value
  File "/usr/local/lib/python3.10/site-packages/django/db/backends/utils.py", line 105, in _execute
    return self.cursor.execute(sql, params)
  File "/usr/local/lib/python3.10/site-packages/django/db/backends/mysql/base.py", line 76, in execute
    return self.cursor.execute(query, args)
  File "/usr/local/lib/python3.10/site-packages/MySQLdb/cursors.py", line 179, in execute
    res = self._query(mogrified_query)
  File "/usr/local/lib/python3.10/site-packages/MySQLdb/cursors.py", line 330, in _query
    db.query(q)
  File "/usr/local/lib/python3.10/site-packages/MySQLdb/connections.py", line 261, in query
    _mysql.connection.query(self, query)
django.db.utils.IntegrityError: (1048, "Column 'category_id' cannot be null")
(1048, "Column 'category_id' cannot be null")
Traceback (most recent call last):
  File "/usr/local/lib/python3.10/site-packages/django/db/backends/utils.py", line 105, in _execute
    return self.cursor.execute(sql, params)
  File "/usr/local/lib/python3.10/site-packages/django/db/backends/mysql/base.py", line 76, in execute
    return self.cursor.execute(query, args)
  File "/usr/local/lib/python3.10/site-packages/MySQLdb/cursors.py", line 179, in execute
    res = self._query(mogrified_query)
  File "/usr/local/lib/python3.10/site-packages/MySQLdb/cursors.py", line 330, in _query
    db.query(q)
  File "/usr/local/lib/python3.10/site-packages/MySQLdb/connections.py", line 261, in query
    _mysql.connection.query(self, query)
MySQLdb.IntegrityError: (1048, "Column 'category_id' cannot be null")

The above exception was the direct cause of the following exception:

Traceback (most recent call last):
  File "/home/user/sources/apps/web_netkeiba_pagesources/models.py", line 194, in update_html
    self.__update_html(driver)
  File "/home/user/sources/apps/web_netkeiba_pagesources/models.py", line 208, in __update_html
    self.save()
  File "/usr/local/lib/python3.10/site-packages/django/db/models/base.py", line 822, in save
    self.save_base(
  File "/usr/local/lib/python3.10/site-packages/django/db/models/base.py", line 906, in save_base
    parent_inserted = self._save_parents(
  File "/usr/local/lib/python3.10/site-packages/django/db/models/base.py", line 959, in _save_parents
    updated = self._save_table(
  File "/usr/local/lib/python3.10/site-packages/django/db/models/base.py", line 1040, in _save_table
    updated = self._do_update(
  File "/usr/local/lib/python3.10/site-packages/django/db/models/base.py", line 1105, in _do_update
    return filtered._update(values) > 0
  File "/usr/local/lib/python3.10/site-packages/django/db/models/query.py", line 1278, in _update
    return query.get_compiler(self.db).execute_sql(CURSOR)
  File "/usr/local/lib/python3.10/site-packages/django/db/models/sql/compiler.py", line 1990, in execute_sql
    cursor = super().execute_sql(result_type)
  File "/usr/local/lib/python3.10/site-packages/django/db/models/sql/compiler.py", line 1562, in execute_sql
    cursor.execute(sql, params)
  File "/usr/local/lib/python3.10/site-packages/django/db/backends/utils.py", line 122, in execute
    return super().execute(sql, params)
  File "/usr/local/lib/python3.10/site-packages/django/db/backends/utils.py", line 79, in execute
    return self._execute_with_wrappers(
  File "/usr/local/lib/python3.10/site-packages/django/db/backends/utils.py", line 92, in _execute_with_wrappers
    return executor(sql, params, many, context)
  File "/usr/local/lib/python3.10/site-packages/django/db/backends/utils.py", line 100, in _execute
    with self.db.wrap_database_errors:
  File "/usr/local/lib/python3.10/site-packages/django/db/utils.py", line 91, in __exit__
    raise dj_exc_value.with_traceback(traceback) from exc_value
  File "/usr/local/lib/python3.10/site-packages/django/db/backends/utils.py", line 105, in _execute
    return self.cursor.execute(sql, params)
  File "/usr/local/lib/python3.10/site-packages/django/db/backends/mysql/base.py", line 76, in execute
    return self.cursor.execute(query, args)
  File "/usr/local/lib/python3.10/site-packages/MySQLdb/cursors.py", line 179, in execute
    res = self._query(mogrified_query)
  File "/usr/local/lib/python3.10/site-packages/MySQLdb/cursors.py", line 330, in _query
    db.query(q)
  File "/usr/local/lib/python3.10/site-packages/MySQLdb/connections.py", line 261, in query
    _mysql.connection.query(self, query)
django.db.utils.IntegrityError: (1048, "Column 'category_id' cannot be null")
(1048, "Column 'category_id' cannot be null")
Traceback (most recent call last):
  File "/usr/local/lib/python3.10/site-packages/django/db/backends/utils.py", line 105, in _execute
    return self.cursor.execute(sql, params)
  File "/usr/local/lib/python3.10/site-packages/django/db/backends/mysql/base.py", line 76, in execute
    return self.cursor.execute(query, args)
  File "/usr/local/lib/python3.10/site-packages/MySQLdb/cursors.py", line 179, in execute
    res = self._query(mogrified_query)
  File "/usr/local/lib/python3.10/site-packages/MySQLdb/cursors.py", line 330, in _query
    db.query(q)
  File "/usr/local/lib/python3.10/site-packages/MySQLdb/connections.py", line 261, in query
    _mysql.connection.query(self, query)
MySQLdb.IntegrityError: (1048, "Column 'category_id' cannot be null")

The above exception was the direct cause of the following exception:

Traceback (most recent call last):
  File "/home/user/sources/apps/web_netkeiba_pagesources/models.py", line 194, in update_html
    self.__update_html(driver)
  File "/home/user/sources/apps/web_netkeiba_pagesources/models.py", line 208, in __update_html
    self.save()
  File "/usr/local/lib/python3.10/site-packages/django/db/models/base.py", line 822, in save
    self.save_base(
  File "/usr/local/lib/python3.10/site-packages/django/db/models/base.py", line 906, in save_base
    parent_inserted = self._save_parents(
  File "/usr/local/lib/python3.10/site-packages/django/db/models/base.py", line 959, in _save_parents
    updated = self._save_table(
  File "/usr/local/lib/python3.10/site-packages/django/db/models/base.py", line 1040, in _save_table
    updated = self._do_update(
  File "/usr/local/lib/python3.10/site-packages/django/db/models/base.py", line 1105, in _do_update
    return filtered._update(values) > 0
  File "/usr/local/lib/python3.10/site-packages/django/db/models/query.py", line 1278, in _update
    return query.get_compiler(self.db).execute_sql(CURSOR)
  File "/usr/local/lib/python3.10/site-packages/django/db/models/sql/compiler.py", line 1990, in execute_sql
    cursor = super().execute_sql(result_type)
  File "/usr/local/lib/python3.10/site-packages/django/db/models/sql/compiler.py", line 1562, in execute_sql
    cursor.execute(sql, params)
  File "/usr/local/lib/python3.10/site-packages/django/db/backends/utils.py", line 122, in execute
    return super().execute(sql, params)
  File "/usr/local/lib/python3.10/site-packages/django/db/backends/utils.py", line 79, in execute
    return self._execute_with_wrappers(
  File "/usr/local/lib/python3.10/site-packages/django/db/backends/utils.py", line 92, in _execute_with_wrappers
    return executor(sql, params, many, context)
  File "/usr/local/lib/python3.10/site-packages/django/db/backends/utils.py", line 100, in _execute
    with self.db.wrap_database_errors:
  File "/usr/local/lib/python3.10/site-packages/django/db/utils.py", line 91, in __exit__
    raise dj_exc_value.with_traceback(traceback) from exc_value
  File "/usr/local/lib/python3.10/site-packages/django/db/backends/utils.py", line 105, in _execute
    return self.cursor.execute(sql, params)
  File "/usr/local/lib/python3.10/site-packages/django/db/backends/mysql/base.py", line 76, in execute
    return self.cursor.execute(query, args)
  File "/usr/local/lib/python3.10/site-packages/MySQLdb/cursors.py", line 179, in execute
    res = self._query(mogrified_query)
  File "/usr/local/lib/python3.10/site-packages/MySQLdb/cursors.py", line 330, in _query
    db.query(q)
  File "/usr/local/lib/python3.10/site-packages/MySQLdb/connections.py", line 261, in query
    _mysql.connection.query(self, query)
django.db.utils.IntegrityError: (1048, "Column 'category_id' cannot be null")
(1048, "Column 'category_id' cannot be null")
Traceback (most recent call last):
  File "/usr/local/lib/python3.10/site-packages/django/db/backends/utils.py", line 105, in _execute
    return self.cursor.execute(sql, params)
  File "/usr/local/lib/python3.10/site-packages/django/db/backends/mysql/base.py", line 76, in execute
    return self.cursor.execute(query, args)
  File "/usr/local/lib/python3.10/site-packages/MySQLdb/cursors.py", line 179, in execute
    res = self._query(mogrified_query)
  File "/usr/local/lib/python3.10/site-packages/MySQLdb/cursors.py", line 330, in _query
    db.query(q)
  File "/usr/local/lib/python3.10/site-packages/MySQLdb/connections.py", line 261, in query
    _mysql.connection.query(self, query)
MySQLdb.IntegrityError: (1048, "Column 'category_id' cannot be null")

The above exception was the direct cause of the following exception:

Traceback (most recent call last):
  File "/home/user/sources/apps/web_netkeiba_pagesources/models.py", line 194, in update_html
    self.__update_html(driver)
  File "/home/user/sources/apps/web_netkeiba_pagesources/models.py", line 208, in __update_html
    self.save()
  File "/usr/local/lib/python3.10/site-packages/django/db/models/base.py", line 822, in save
    self.save_base(
  File "/usr/local/lib/python3.10/site-packages/django/db/models/base.py", line 906, in save_base
    parent_inserted = self._save_parents(
  File "/usr/local/lib/python3.10/site-packages/django/db/models/base.py", line 959, in _save_parents
    updated = self._save_table(
  File "/usr/local/lib/python3.10/site-packages/django/db/models/base.py", line 1040, in _save_table
    updated = self._do_update(
  File "/usr/local/lib/python3.10/site-packages/django/db/models/base.py", line 1105, in _do_update
    return filtered._update(values) > 0
  File "/usr/local/lib/python3.10/site-packages/django/db/models/query.py", line 1278, in _update
    return query.get_compiler(self.db).execute_sql(CURSOR)
  File "/usr/local/lib/python3.10/site-packages/django/db/models/sql/compiler.py", line 1990, in execute_sql
    cursor = super().execute_sql(result_type)
  File "/usr/local/lib/python3.10/site-packages/django/db/models/sql/compiler.py", line 1562, in execute_sql
    cursor.execute(sql, params)
  File "/usr/local/lib/python3.10/site-packages/django/db/backends/utils.py", line 122, in execute
    return super().execute(sql, params)
  File "/usr/local/lib/python3.10/site-packages/django/db/backends/utils.py", line 79, in execute
    return self._execute_with_wrappers(
  File "/usr/local/lib/python3.10/site-packages/django/db/backends/utils.py", line 92, in _execute_with_wrappers
    return executor(sql, params, many, context)
  File "/usr/local/lib/python3.10/site-packages/django/db/backends/utils.py", line 100, in _execute
    with self.db.wrap_database_errors:
  File "/usr/local/lib/python3.10/site-packages/django/db/utils.py", line 91, in __exit__
    raise dj_exc_value.with_traceback(traceback) from exc_value
  File "/usr/local/lib/python3.10/site-packages/django/db/backends/utils.py", line 105, in _execute
    return self.cursor.execute(sql, params)
  File "/usr/local/lib/python3.10/site-packages/django/db/backends/mysql/base.py", line 76, in execute
    return self.cursor.execute(query, args)
  File "/usr/local/lib/python3.10/site-packages/MySQLdb/cursors.py", line 179, in execute
    res = self._query(mogrified_query)
  File "/usr/local/lib/python3.10/site-packages/MySQLdb/cursors.py", line 330, in _query
    db.query(q)
  File "/usr/local/lib/python3.10/site-packages/MySQLdb/connections.py", line 261, in query
    _mysql.connection.query(self, query)
django.db.utils.IntegrityError: (1048, "Column 'category_id' cannot be null")
(1048, "Column 'category_id' cannot be null")
Traceback (most recent call last):
  File "/usr/local/lib/python3.10/site-packages/django/db/backends/utils.py", line 105, in _execute
    return self.cursor.execute(sql, params)
  File "/usr/local/lib/python3.10/site-packages/django/db/backends/mysql/base.py", line 76, in execute
    return self.cursor.execute(query, args)
  File "/usr/local/lib/python3.10/site-packages/MySQLdb/cursors.py", line 179, in execute
    res = self._query(mogrified_query)
  File "/usr/local/lib/python3.10/site-packages/MySQLdb/cursors.py", line 330, in _query
    db.query(q)
  File "/usr/local/lib/python3.10/site-packages/MySQLdb/connections.py", line 261, in query
    _mysql.connection.query(self, query)
MySQLdb.IntegrityError: (1048, "Column 'category_id' cannot be null")

The above exception was the direct cause of the following exception:

Traceback (most recent call last):
  File "/home/user/sources/apps/web_netkeiba_pagesources/models.py", line 217, in update_html
    self.__update_html(driver)
  File "/home/user/sources/apps/web_netkeiba_pagesources/models.py", line 231, in __update_html
    self.save()
  File "/usr/local/lib/python3.10/site-packages/django/db/models/base.py", line 822, in save
    self.save_base(
  File "/usr/local/lib/python3.10/site-packages/django/db/models/base.py", line 906, in save_base
    parent_inserted = self._save_parents(
  File "/usr/local/lib/python3.10/site-packages/django/db/models/base.py", line 959, in _save_parents
    updated = self._save_table(
  File "/usr/local/lib/python3.10/site-packages/django/db/models/base.py", line 1040, in _save_table
    updated = self._do_update(
  File "/usr/local/lib/python3.10/site-packages/django/db/models/base.py", line 1105, in _do_update
    return filtered._update(values) > 0
  File "/usr/local/lib/python3.10/site-packages/django/db/models/query.py", line 1278, in _update
    return query.get_compiler(self.db).execute_sql(CURSOR)
  File "/usr/local/lib/python3.10/site-packages/django/db/models/sql/compiler.py", line 1990, in execute_sql
    cursor = super().execute_sql(result_type)
  File "/usr/local/lib/python3.10/site-packages/django/db/models/sql/compiler.py", line 1562, in execute_sql
    cursor.execute(sql, params)
  File "/usr/local/lib/python3.10/site-packages/django/db/backends/utils.py", line 79, in execute
    return self._execute_with_wrappers(
  File "/usr/local/lib/python3.10/site-packages/django/db/backends/utils.py", line 92, in _execute_with_wrappers
    return executor(sql, params, many, context)
  File "/usr/local/lib/python3.10/site-packages/django/db/backends/utils.py", line 100, in _execute
    with self.db.wrap_database_errors:
  File "/usr/local/lib/python3.10/site-packages/django/db/utils.py", line 91, in __exit__
    raise dj_exc_value.with_traceback(traceback) from exc_value
  File "/usr/local/lib/python3.10/site-packages/django/db/backends/utils.py", line 105, in _execute
    return self.cursor.execute(sql, params)
  File "/usr/local/lib/python3.10/site-packages/django/db/backends/mysql/base.py", line 76, in execute
    return self.cursor.execute(query, args)
  File "/usr/local/lib/python3.10/site-packages/MySQLdb/cursors.py", line 179, in execute
    res = self._query(mogrified_query)
  File "/usr/local/lib/python3.10/site-packages/MySQLdb/cursors.py", line 330, in _query
    db.query(q)
  File "/usr/local/lib/python3.10/site-packages/MySQLdb/connections.py", line 261, in query
    _mysql.connection.query(self, query)
django.db.utils.IntegrityError: (1048, "Column 'category_id' cannot be null")
(1048, "Column 'category_id' cannot be null")
Traceback (most recent call last):
  File "/usr/local/lib/python3.10/site-packages/django/db/backends/utils.py", line 105, in _execute
    return self.cursor.execute(sql, params)
  File "/usr/local/lib/python3.10/site-packages/django/db/backends/mysql/base.py", line 76, in execute
    return self.cursor.execute(query, args)
  File "/usr/local/lib/python3.10/site-packages/MySQLdb/cursors.py", line 179, in execute
    res = self._query(mogrified_query)
  File "/usr/local/lib/python3.10/site-packages/MySQLdb/cursors.py", line 330, in _query
    db.query(q)
  File "/usr/local/lib/python3.10/site-packages/MySQLdb/connections.py", line 261, in query
    _mysql.connection.query(self, query)
MySQLdb.IntegrityError: (1048, "Column 'category_id' cannot be null")

The above exception was the direct cause of the following exception:

Traceback (most recent call last):
  File "/home/user/sources/apps/web_netkeiba_pagesources/models.py", line 217, in update_html
    self.__update_html(driver)
  File "/home/user/sources/apps/web_netkeiba_pagesources/models.py", line 231, in __update_html
    self.save()
  File "/usr/local/lib/python3.10/site-packages/django/db/models/base.py", line 822, in save
    self.save_base(
  File "/usr/local/lib/python3.10/site-packages/django/db/models/base.py", line 906, in save_base
    parent_inserted = self._save_parents(
  File "/usr/local/lib/python3.10/site-packages/django/db/models/base.py", line 959, in _save_parents
    updated = self._save_table(
  File "/usr/local/lib/python3.10/site-packages/django/db/models/base.py", line 1040, in _save_table
    updated = self._do_update(
  File "/usr/local/lib/python3.10/site-packages/django/db/models/base.py", line 1105, in _do_update
    return filtered._update(values) > 0
  File "/usr/local/lib/python3.10/site-packages/django/db/models/query.py", line 1278, in _update
    return query.get_compiler(self.db).execute_sql(CURSOR)
  File "/usr/local/lib/python3.10/site-packages/django/db/models/sql/compiler.py", line 1990, in execute_sql
    cursor = super().execute_sql(result_type)
  File "/usr/local/lib/python3.10/site-packages/django/db/models/sql/compiler.py", line 1562, in execute_sql
    cursor.execute(sql, params)
  File "/usr/local/lib/python3.10/site-packages/django/db/backends/utils.py", line 79, in execute
    return self._execute_with_wrappers(
  File "/usr/local/lib/python3.10/site-packages/django/db/backends/utils.py", line 92, in _execute_with_wrappers
    return executor(sql, params, many, context)
  File "/usr/local/lib/python3.10/site-packages/django/db/backends/utils.py", line 100, in _execute
    with self.db.wrap_database_errors:
  File "/usr/local/lib/python3.10/site-packages/django/db/utils.py", line 91, in __exit__
    raise dj_exc_value.with_traceback(traceback) from exc_value
  File "/usr/local/lib/python3.10/site-packages/django/db/backends/utils.py", line 105, in _execute
    return self.cursor.execute(sql, params)
  File "/usr/local/lib/python3.10/site-packages/django/db/backends/mysql/base.py", line 76, in execute
    return self.cursor.execute(query, args)
  File "/usr/local/lib/python3.10/site-packages/MySQLdb/cursors.py", line 179, in execute
    res = self._query(mogrified_query)
  File "/usr/local/lib/python3.10/site-packages/MySQLdb/cursors.py", line 330, in _query
    db.query(q)
  File "/usr/local/lib/python3.10/site-packages/MySQLdb/connections.py", line 261, in query
    _mysql.connection.query(self, query)
django.db.utils.IntegrityError: (1048, "Column 'category_id' cannot be null")
(1048, "Column 'category_id' cannot be null")
Traceback (most recent call last):
  File "/usr/local/lib/python3.10/site-packages/django/db/backends/utils.py", line 105, in _execute
    return self.cursor.execute(sql, params)
  File "/usr/local/lib/python3.10/site-packages/django/db/backends/mysql/base.py", line 76, in execute
    return self.cursor.execute(query, args)
  File "/usr/local/lib/python3.10/site-packages/MySQLdb/cursors.py", line 179, in execute
    res = self._query(mogrified_query)
  File "/usr/local/lib/python3.10/site-packages/MySQLdb/cursors.py", line 330, in _query
    db.query(q)
  File "/usr/local/lib/python3.10/site-packages/MySQLdb/connections.py", line 261, in query
    _mysql.connection.query(self, query)
MySQLdb.IntegrityError: (1048, "Column 'category_id' cannot be null")

The above exception was the direct cause of the following exception:

Traceback (most recent call last):
  File "/home/user/sources/apps/web_netkeiba_pagesources/models.py", line 217, in update_html
    self.__update_html(driver)
  File "/home/user/sources/apps/web_netkeiba_pagesources/models.py", line 231, in __update_html
    self.save()
  File "/usr/local/lib/python3.10/site-packages/django/db/models/base.py", line 822, in save
    self.save_base(
  File "/usr/local/lib/python3.10/site-packages/django/db/models/base.py", line 906, in save_base
    parent_inserted = self._save_parents(
  File "/usr/local/lib/python3.10/site-packages/django/db/models/base.py", line 959, in _save_parents
    updated = self._save_table(
  File "/usr/local/lib/python3.10/site-packages/django/db/models/base.py", line 1040, in _save_table
    updated = self._do_update(
  File "/usr/local/lib/python3.10/site-packages/django/db/models/base.py", line 1105, in _do_update
    return filtered._update(values) > 0
  File "/usr/local/lib/python3.10/site-packages/django/db/models/query.py", line 1278, in _update
    return query.get_compiler(self.db).execute_sql(CURSOR)
  File "/usr/local/lib/python3.10/site-packages/django/db/models/sql/compiler.py", line 1990, in execute_sql
    cursor = super().execute_sql(result_type)
  File "/usr/local/lib/python3.10/site-packages/django/db/models/sql/compiler.py", line 1562, in execute_sql
    cursor.execute(sql, params)
  File "/usr/local/lib/python3.10/site-packages/django/db/backends/utils.py", line 79, in execute
    return self._execute_with_wrappers(
  File "/usr/local/lib/python3.10/site-packages/django/db/backends/utils.py", line 92, in _execute_with_wrappers
    return executor(sql, params, many, context)
  File "/usr/local/lib/python3.10/site-packages/django/db/backends/utils.py", line 100, in _execute
    with self.db.wrap_database_errors:
  File "/usr/local/lib/python3.10/site-packages/django/db/utils.py", line 91, in __exit__
    raise dj_exc_value.with_traceback(traceback) from exc_value
  File "/usr/local/lib/python3.10/site-packages/django/db/backends/utils.py", line 105, in _execute
    return self.cursor.execute(sql, params)
  File "/usr/local/lib/python3.10/site-packages/django/db/backends/mysql/base.py", line 76, in execute
    return self.cursor.execute(query, args)
  File "/usr/local/lib/python3.10/site-packages/MySQLdb/cursors.py", line 179, in execute
    res = self._query(mogrified_query)
  File "/usr/local/lib/python3.10/site-packages/MySQLdb/cursors.py", line 330, in _query
    db.query(q)
  File "/usr/local/lib/python3.10/site-packages/MySQLdb/connections.py", line 261, in query
    _mysql.connection.query(self, query)
django.db.utils.IntegrityError: (1048, "Column 'category_id' cannot be null")
(1048, "Column 'category_id' cannot be null")
Traceback (most recent call last):
  File "/usr/local/lib/python3.10/site-packages/django/db/backends/utils.py", line 105, in _execute
    return self.cursor.execute(sql, params)
  File "/usr/local/lib/python3.10/site-packages/django/db/backends/mysql/base.py", line 76, in execute
    return self.cursor.execute(query, args)
  File "/usr/local/lib/python3.10/site-packages/MySQLdb/cursors.py", line 179, in execute
    res = self._query(mogrified_query)
  File "/usr/local/lib/python3.10/site-packages/MySQLdb/cursors.py", line 330, in _query
    db.query(q)
  File "/usr/local/lib/python3.10/site-packages/MySQLdb/connections.py", line 261, in query
    _mysql.connection.query(self, query)
MySQLdb.IntegrityError: (1048, "Column 'category_id' cannot be null")

The above exception was the direct cause of the following exception:

Traceback (most recent call last):
  File "/home/user/sources/apps/web_netkeiba_pagesources/models.py", line 217, in update_html
    self.__update_html(driver)
  File "/home/user/sources/apps/web_netkeiba_pagesources/models.py", line 231, in __update_html
    self.save()
  File "/usr/local/lib/python3.10/site-packages/django/db/models/base.py", line 822, in save
    self.save_base(
  File "/usr/local/lib/python3.10/site-packages/django/db/models/base.py", line 906, in save_base
    parent_inserted = self._save_parents(
  File "/usr/local/lib/python3.10/site-packages/django/db/models/base.py", line 959, in _save_parents
    updated = self._save_table(
  File "/usr/local/lib/python3.10/site-packages/django/db/models/base.py", line 1040, in _save_table
    updated = self._do_update(
  File "/usr/local/lib/python3.10/site-packages/django/db/models/base.py", line 1105, in _do_update
    return filtered._update(values) > 0
  File "/usr/local/lib/python3.10/site-packages/django/db/models/query.py", line 1278, in _update
    return query.get_compiler(self.db).execute_sql(CURSOR)
  File "/usr/local/lib/python3.10/site-packages/django/db/models/sql/compiler.py", line 1990, in execute_sql
    cursor = super().execute_sql(result_type)
  File "/usr/local/lib/python3.10/site-packages/django/db/models/sql/compiler.py", line 1562, in execute_sql
    cursor.execute(sql, params)
  File "/usr/local/lib/python3.10/site-packages/django/db/backends/utils.py", line 79, in execute
    return self._execute_with_wrappers(
  File "/usr/local/lib/python3.10/site-packages/django/db/backends/utils.py", line 92, in _execute_with_wrappers
    return executor(sql, params, many, context)
  File "/usr/local/lib/python3.10/site-packages/django/db/backends/utils.py", line 100, in _execute
    with self.db.wrap_database_errors:
  File "/usr/local/lib/python3.10/site-packages/django/db/utils.py", line 91, in __exit__
    raise dj_exc_value.with_traceback(traceback) from exc_value
  File "/usr/local/lib/python3.10/site-packages/django/db/backends/utils.py", line 105, in _execute
    return self.cursor.execute(sql, params)
  File "/usr/local/lib/python3.10/site-packages/django/db/backends/mysql/base.py", line 76, in execute
    return self.cursor.execute(query, args)
  File "/usr/local/lib/python3.10/site-packages/MySQLdb/cursors.py", line 179, in execute
    res = self._query(mogrified_query)
  File "/usr/local/lib/python3.10/site-packages/MySQLdb/cursors.py", line 330, in _query
    db.query(q)
  File "/usr/local/lib/python3.10/site-packages/MySQLdb/connections.py", line 261, in query
    _mysql.connection.query(self, query)
django.db.utils.IntegrityError: (1048, "Column 'category_id' cannot be null")
ログインが必要です。
Traceback (most recent call last):
  File "/home/user/sources/apps/web_netkeiba_pagesources/models.py", line 217, in update_html
    self.__update_html(driver)
  File "/home/user/sources/apps/web_netkeiba_pagesources/models.py", line 232, in __update_html
    raise PermissionError("ログインが必要です。")
PermissionError: ログインが必要です。
ログインが必要です。
Traceback (most recent call last):
  File "/home/user/sources/apps/web_netkeiba_pagesources/models.py", line 219, in update_html
    self.__update_html(driver)
  File "/home/user/sources/apps/web_netkeiba_pagesources/models.py", line 235, in __update_html
    raise PermissionError("ログインが必要です。")
PermissionError: ログインが必要です。
