Database access not allowed, use the "django_db" mark, or the "db" or "transactional_db" fixtures to enable it.
Traceback (most recent call last):
  File "/home/user/sources/scraping/models/netkeiba_pages.py", line 142, in update_html
    self.__update_html(driver)
  File "/home/user/sources/scraping/models/login_for_scraping.py", line 51, in wrapper
    LoginForScraping.objects.get_or_create(domain=domain)
  File "/usr/local/lib/python3.10/site-packages/django/db/models/manager.py", line 87, in manager_method
    return getattr(self.get_queryset(), name)(*args, **kwargs)
  File "/usr/local/lib/python3.10/site-packages/django/db/models/query.py", line 948, in get_or_create
    return self.get(**kwargs), False
  File "/usr/local/lib/python3.10/site-packages/django/db/models/query.py", line 645, in get
    num = len(clone)
  File "/usr/local/lib/python3.10/site-packages/django/db/models/query.py", line 382, in __len__
    self._fetch_all()
  File "/usr/local/lib/python3.10/site-packages/django/db/models/query.py", line 1928, in _fetch_all
    self._result_cache = list(self._iterable_class(self))
  File "/usr/local/lib/python3.10/site-packages/django/db/models/query.py", line 91, in __iter__
    results = compiler.execute_sql(
  File "/usr/local/lib/python3.10/site-packages/django/db/models/sql/compiler.py", line 1560, in execute_sql
    cursor = self.connection.cursor()
  File "/usr/local/lib/python3.10/site-packages/django/utils/asyncio.py", line 26, in inner
    return func(*args, **kwargs)
  File "/usr/local/lib/python3.10/site-packages/django/db/backends/base/base.py", line 316, in cursor
    return self._cursor()
  File "/usr/local/lib/python3.10/site-packages/django/db/backends/base/base.py", line 292, in _cursor
    self.ensure_connection()
  File "/usr/local/lib/python3.10/site-packages/pytest_django/plugin.py", line 803, in _blocking_wrapper
    raise RuntimeError(
RuntimeError: Database access not allowed, use the "django_db" mark, or the "db" or "transactional_db" fixtures to enable it.
